Workbook
Name CHOSEN_FISH: Framework!$M$10
Name CHOSEN_GREEN: Framework!$M$9
Name CHOSEN_REGION: Framework!$M$11
Name COST_OF_CAPITAL: Funding!$D$5
Name DEBT_INTEREST_RATE: Funding!$D$8
Name FISH_TANK: System_Parameters!$Q$10
Name HYDROPONIC_AREA: System_Parameters!$P$4
Name HYDROPONICS_UNIT: System_Parameters!$P$5
Name MAINTENANCE_PERCENTAGE: Investment!$B$6
Name PRODUCTIVITY_FACTOR: Investment!$H$7
Name RAS_AREA: System_Parameters!$P$8
Name RAS_VOLUME: System_Parameters!$P$10
Name TOTAL_AREA: Framework!$M$6
Name WACC: Funding!$L$5
Name YEAR_FISH_PRODUCTION: System_Parameters!$R$8
Name YEAR_GREEN_PRODUCTION: System_Parameters!$R$4
Name PARTS_PERCENTAGE: Investment!$B$7
Name PARTS_PERCENTAGE: Investment!$B$7
Name PRODUCTIVITY_FACTOR: Investment!$H$7

Sheet kWh Estimativa
A1: Estimativa de Consumo Elétrico (kWh/ano) — Fórmulas por Volume (RAS) e Área (Hidroponia)
A3: Parâmetros de Entrada (ajuste aqui)
A4: Volume total do RAS (m³) | D4: 10
A5: Área de Hidroponia (m²) | D5: 100
A6: Número de tanques de peixe | D6: 5
A8: Item | B8: Base de cálculo | C8: Densidade (W/unidade) | D8: Horas/dia | E8: Fórmula (kWh/ano) | F8: kWh/ano estimado | G8: Observação
A9: HIDROPONIA — escala por m²
A10: Iluminação (LED suplementar) | B10: W/m² | C10: 80-120 (méd 100) | D10: 12 | E10: 100 x D5 x 12h x 365 / 1000 | F10: =100*$D$5*12*365/1000 | G10: Iluminação suplementar, ciclo 12h/dia
A11: Ventiladores (exaustão) | B11: W/m² | C11: 5-10 (méd 7.5) | D11: 12 | E11: 7.5 x D5 x 12h x 365 / 1000 | F11: =7.5*$D$5*12*365/1000 | G11: Ciclado por termostato
A12: De-humidifier | B12: W/m² | C12: 15-30 (méd 22.5) | D12: 8 | E12: 22.5 x D5 x 8h x 365 / 1000 | F12: =22.5*$D$5*8*365/1000 | G12: Uso intermitente conforme umidade
A13: Hanging/moving Gutter system | B13: W/m² | C13: 2-4 (méd 3) | D13: 24 | E13: 3 x D5 x 24h x 365 / 1000 | F13: =3*$D$5*24*365/1000 | G13: Motor de movimentação intermitente
A14: Hydroponics Pump | B14: W/m² | C14: 2-4 (méd 3) | D14: 24 | E14: 3 x D5 x 24h x 365 / 1000 | F14: =3*$D$5*24*365/1000 | G14: Recirculação contínua da solução nutritiva
A15: RAS — escala por m³ (volume de água)
A16: RAS Pump | B16: W/m³ | C16: 10-20 (méd 15) | D16: 24 | E16: 15 x D4 x 24h x 365 / 1000 | F16: =15*$D$4*24*365/1000 | G16: Recirculação contínua, baixa carga
A17: Gas Exchange | B17: W/m³ | C17: 3-6 (méd 4.5) | D17: 24 | E17: 4.5 x D4 x 24h x 365 / 1000 | F17: =4.5*$D$4*24*365/1000 | G17: Degasagem contínua
A18: Oxygen enrichment | B18: W/m³ | C18: 80-120 (méd 100) | D18: 24 | E18: 100 x D4 x 24h x 365 / 1000 | F18: =100*$D$4*24*365/1000 | G18: Gerador/concentrador de O₂, alto consumo
A19: Ozone enrichment | B19: W/m³ | C19: 10-15 (méd 12.5) | D19: 12 | E19: 12.5 x D4 x 12h x 365 / 1000 | F19: =12.5*$D$4*12*365/1000 | G19: Gerador de ozônio, ciclado
A20: Heat Exchanger (elétrico) | B20: W/m³ | C20: 150-250 (méd 200) | D20: 4 | E20: 200 x D4 x 4h x 365 / 1000 | F20: =200*$D$4*4*365/1000 | G20: Ciclo termostático equivalente
A21: UV-sterilization | B21: W/m³ | C21: 15-25 (méd 20) | D21: 24 | E21: 20 x D4 x 24h x 365 / 1000 | F21: =20*$D$4*24*365/1000 | G21: Proporcional à vazão tratada
A22: USBR (denitrificação) | B22: W/m³ | C22: 3-5 (méd 4) | D22: 24 | E22: 4 x D4 x 24h x 365 / 1000 | F22: =4*$D$4*24*365/1000 | G22: Pequena bomba de alimentação do reator
A23: Drum Filter | B23: W/m³ (equiv.) | C23: 2-4 (méd 3) | D23: 2 | E23: 3 x D4 x 2h x 365 / 1000 | F23: =3*$D$4*2*365/1000 | G23: Motor potente, duty cycle baixo (~10%)
A24: Aerobic mineralization | B24: W/m³ | C24: 30-50 (méd 40) | D24: 24 | E24: 40 x D4 x 24h x 365 / 1000 | F24: =40*$D$4*24*365/1000 | G24: Aeração/mistura contínua
A25: UASB Mineralization | B25: W/m³ | C25: 2-3 (méd 2.5) | D25: 24 | E25: 2.5 x D4 x 24h x 365 / 1000 | F25: =2.5*$D$4*24*365/1000 | G25: Fluxo ascendente passivo + bomba pequena
A26: EGSB Mineralization | B26: W/m³ | C26: 8-12 (méd 10) | D26: 24 | E26: 10 x D4 x 24h x 365 / 1000 | F26: =10*$D$4*24*365/1000 | G26: Recirculação p/ velocidade ascensional alta
A27: Gravity Separation (RFS) | B27: W/m³ | C27: 1-2 (méd 1.5) | D27: 2 | E27: 1.5 x D4 x 2h x 365 / 1000 | F27: =1.5*$D$4*2*365/1000 | G27: Quase todo passivo, bomba de purga do lodo
A28: Biofloc (aeração/mistura) | B28: W/m³ | C28: 15-25 (méd 20) | D28: 24 | E28: 20 x D4 x 24h x 365 / 1000 | F28: =20*$D$4*24*365/1000 | G28: Requer aeração/mistura contínua
A29: Desalinização/RO | B29: W/m³ | C29: 300-500 (méd 400) | D29: 4 | E29: 400 x D4 x 4h x 365 / 1000 | F29: =400*$D$4*4*365/1000 | G29: Alta potência, uso limitado a poucas horas
A30: Hot and Cold Water tank | B30: W/m³ | C30: 100-150 (méd 125) | D30: 4 | E30: 125 x D4 x 4h x 365 / 1000 | F30: =125*$D$4*4*365/1000 | G30: Ciclo termostático equivalente
A31: POR TANQUE — escala por número de tanques
A32: pH sensor | B32: W/tanque | C32: 2-2 (méd 2) | D32: 24 | E32: 2 x D6 x 24h x 365 / 1000 | F32: =2*$D$6*24*365/1000 | G32: Eletrônica de monitoramento contínuo
A33: Aeration Pump | B33: W/tanque | C33: 30-50 (méd 40) | D33: 24 | E33: 40 x D6 x 24h x 365 / 1000 | F33: =40*$D$6*24*365/1000 | G33: Aeração do tanque de peixe, contínua
A34: TAN sensor | B34: W/tanque | C34: 3-3 (méd 3) | D34: 24 | E34: 3 x D6 x 24h x 365 / 1000 | F34: =3*$D$6*24*365/1000 | G34: Sonda contínua
A35: DO sensor | B35: W/tanque | C35: 2-2 (méd 2) | D35: 24 | E35: 2 x D6 x 24h x 365 / 1000 | F35: =2*$D$6*24*365/1000 | G35: Sonda contínua
A36: EC sensor | B36: W/tanque | C36: 2-2 (méd 2) | D36: 24 | E36: 2 x D6 x 24h x 365 / 1000 | F36: =2*$D$6*24*365/1000 | G36: Sonda contínua
A37: Automatic Feeder | B37: W/tanque | C37: 3-6 (méd 4.5) | D37: 24 | E37: 4.5 x D6 x 24h x 365 / 1000 | F37: =4.5*$D$6*24*365/1000 | G37: Controlador em standby + ciclos curtos
A38: Fish-pump / escalator | B38: W/tanque | C38: 400-600 (méd 500) | D38: 0.1 | E38: 500 x D6 x 0.1h x 365 / 1000 | F38: =500*$D$6*0.1*365/1000 | G38: Uso pontual (despesca, ~6 min/dia)
A39: TOTAL ESTIMADO (kWh/ano) | F39: =SUM(F9:F38)
A41: Notas: (1) Cada linha usa densidade média (W/unidade) x variável de escala (m³, m² ou nº tanques) x horas/dia x 365 / 1000. (2) Itens sem coluna de 'W/unidade' porque a fórmula usa a densidade média direto na coluna E/F — ajuste os inputs em D4:D6 para recalcular tudo automaticamente. (3) Itens puramente passivos (RAS enclosure, Sump, Fish Tank, Biofilter estrutural, Greenhouse, Biologic/Periphyton Surface Area, Solar Panels, Emergency generator) não estão nesta tabela pois não consomem eletricidade de rede continuamente.

Sheet Model_test
D2: 1 | G2: max space | H2: 20000
D3: =SUM(D5,D6) | H3: =(F6/H6)*D6+(F5/H5)*D5 | I3: =SUM(I5:I6)
D4: binary | F4: Qty | G4: Unit price | H4: size plants/m2
C5: Tilapia | D5: 1 | F5: 10000 | G5: 5 | H5: 1 | I5: =G5*F5*D5
C6: Trout | D6: 0 | F6: 10000 | G6: 3 | H6: 1 | I6: =G6*F6*D6

Sheet Alternatives
D2: 1 | G2: max space | H2: 20000
D3: =SUM(D5,D6) | H3: =(F6/H6)*D6+(F5/H5)*D5 | I3: =SUM(I5:I6)
D4: binary | F4: Qty | G4: Unit price | H4: size plants/m2
C5: Tilapia | D5: 1 | F5: 0 | G5: 2 | H5: 100 | I5: =G5*F5*D5
C6: Trout | D6: 0 | F6: 0 | G6: 3 | H6: 1 | I6: =G6*F6*D6

Sheet Parameters
A1: TIMMONS
A2: Change UV bulbs at least once a year.
A3: Power failure is probably the most common emergency and the one most easily monitored.
A4: Backup electricity can be provided by a generator that is fueled with gasoline, diesel, or natural or propane gas.
A5: At a minimum the laboratory will include equipment for water quality analysis, a microscope for fish health management, a refrigerator for chemicals and samples, and a computer for data analysis and storage.
A6: Some Norwegian salmon fanners use grading to cull the smallest, least efficient feeders and might remove as much as 50% of the population. Maintaining inefficient feeders can create a 30-50% increase in production costs;
A7: A monthly sampling interval is a reasonable compromise between minimizing stress and maximizing accuracy.
A9: FAO
A10: o guarantee a long life span and energy efficiency. Top-quality pumps will maintain their pumping capacity and efficiency for least 1–2 years, with an overall life span of 3–5 years, w
A11: the small-scale units described in this publication need a flow rate of 2 000 litres/h at a head height of 1.5 meters; a submersible pump of this capacity would consume 25–50 W/h.
A12: The suggested rate is 5–8 litres of air per minute for each cubic metre of water, coming from at least 2 air stones in different locations in the fish tank. Densely stocked units may require considerably more.
A13: Tilapias can be aggressive, especially in low densities, because males are territorial. Therefore, the fish should be kept at high densities in the grow-out tanks. Some farms only use male fish in the grow-out tanks;
... A36: Tariffs dashboard | International Benchmarking Network
B52: GlobalPetrolPrices.com | E52: IBNET/Global Water Intelligence 2012 tariff survey
A54: Region | B54: Electricity Low (/kWh) | C54: ElectricityAvg(/kWh) | D54: Electricity High (/kWh) | E54: WaterLow(/m³) | F54: Water Avg (/m3) | G54: WaterHigh(/m³)
A55: Africa | B55: 0.107 | C55: 0.133 | D55: 0.193 | E55: 0.03 | F55: 0.5 | G55: 2
A56: Asia | B56: 0.088 | C56: 0.107 | D56: 0.15 | E56: 0.01 | F56: 0.3 | G56: 1.5
A57: North America | B57: 0.15 | C57: 0.165 | D57: 0.2 | E57: 0.42 | F57: 1 | G57: 1.6
A58: South America | B58: 0.165 | C58: 0.203 | D58: 0.23 | E58: 0.2 | F58: 0.8 | G58: 1.5
A59: Europe | B59: 0.213 | C59: 0.24 | D59: 0.37 | E59: 1 | F59: 3.5 | G59: 9.21
A60: Oceania | B60: 0.26 | C60: 0.266 | D60: 0.28 | E60: 1 | F60: 4 | G60: 6.47

Sheet Multispecies_test
A1: Parameters
A3: Sizing | K3: Revenue | L3: =J12*I12*H12+H13*I13*J13+H14*I14*J14+H15*I15*J15+H16*I16*J16+H17*I17*J17+H18*I18*J18+H19*I19*J19+H20*I20*J20+H21*I21*J21+H22*I22*J22
A4: Plant-fish mass ratio (PFRM)(Kg/kg) | E4: 3.1
A5: Average tank volume (m³) | E5: 8
A6: Height tank (m) | E6: 1.2 | K6: Production per m² | L6: =H12*J12+H13*J13+H14*J14+H15*J15+H16*J16+H17*J17+H18*J18+H19*J19+H20*J20+H21*J21+H22*J22 | M6: <=
A7: Administration, Logistics and Service necessary area (%) | E7: 0.15
C9: Life Cycle (days/ organism) | D9: Space occupied (organism /(m²/m³)) | E9: Organism production(kg/organism) | F9: Full renew (changes/ year) | G9: Density (kg/m²) | H9: Space yield (kg/m²) | I9: Price per kg ($) | L9: Used area | M9: Total Area (m2)
M10: =TOTAL_AREA
A11: Greens | J11: CHOICE in Kg | M11: Production Area (m2) | N11: Area Hydroponic (m²) | P11: Yearly Gross Production (kg)
A12: Tomato | C12: 365 | D12: 3.9 | E12: 10 | F12: =365/C12 | G12: =E12*D12 | H12: =F12*E12*D12 | I12: =VLOOKUP(A12,$A$37:$C$51,3,0) | J12: 0 | M12: =M10*(1-E7) | N12: =M12-N14 | O12: =N12/M12 | P12: =N12*H12
A13: Lettuce | B13: Lactuca sativa | C13: 35 | D13: 25 | E13: 0.2 | F13: =365/C13 | G13: =E13*D13 | H13: =F13*E13*D13 | I13: =VLOOKUP(A13,$A$37:$C$51,3,0) | J13: 0 | N13: Area RAS (m²)
A14: Chicória | B14: Cichorium intybus | C14: 28 | D14: 16 | E14: 0.13232 | F14: =365/C14 | G14: =E14*D14 | H14: =F14*E14*D14 | I14: =VLOOKUP(A14,$A$37:$C$51,3,0) | J14: 0 | N14: =M12/(1+E4*H25/H12) | O14: =N14/M12 | P14: =N14*H25
A15: Almeirão Pão de Açúcar | B15: Cichorium intybus | C15: 28 | D15: 16 | E15: 0.09816 | F15: =365/C15 | G15: =E15*D15 | H15: =F15*E15*D15 | I15: =VLOOKUP(A15,$A$37:$C$51,3,0) | J15: 0 | N15: Volume RAS (m³)
A16: Almeirão Amargo | B16: Cichorium intybus | C16: 28 | D16: 16 | E16: 0.11576 | F16: =365/C16 | G16: =E16*D16 | H16: =F16*E16*D16 | I16: =VLOOKUP(A16,$A$37:$C$51,3,0) | J16: 0 | N16: =N14/E6 | O16: =ROUND(N14/E5,0) | P16: RAS Tanks
A17: Espinafre | B17: Spinacia oleracea | C17: 28 | D17: 16 | E17: 0.07872 | F17: =365/C17 | G17: =E17*D17 | H17: =F17*E17*D17 | I17: =VLOOKUP(A17,$A$37:$C$51,3,0) | J17: 0
A18: Alface | B18: Lactuca sativa | C18: 28 | D18: 16 | E18: 0.07872 | F18: =365/C18 | G18: =E18*D18 | H18: =F18*E18*D18 | I18: =VLOOKUP(A18,$A$37:$C$51,3,0) | J18: 0
A19: Salsinha | B19: Petroselinum crispum | C19: 28 | D19: 16 | E19: 0.03587 | F19: =365/C19 | G19: =E19*D19 | H19: =F19*E19*D19 | I19: =VLOOKUP(A19,$A$37:$C$51,3,0) | J19: 0
A20: Manjericão | B20: Ocimum basilicum | C20: 28 | D20: 16 | E20: 0.04206 | F20: =365/C20 | G20: =E20*D20 | H20: =F20*E20*D20 | I20: =VLOOKUP(A20,$A$37:$C$51,3,0) | J20: 351.25365
A21: Agrião | B21: Nasturtium officinale | C21: 28 | D21: 16 | E21: 0.07369 | F21: =365/C21 | G21: =E21*D21 | H21: =F21*E21*D21 | I21: =VLOOKUP(A21,$A$37:$C$51,3,0) | J21: 0
A22: Cebolinha | B22: Allium schoenoprasum | C22: 28 | D22: 16 | E22: 0.02525 | F22: =365/C22 | G22: =E22*D22 | H22: =F22*E22*D22 | I22: =VLOOKUP(A22,$A$37:$C$51,3,0) | J22: 0
A24: Chosen Aquatic
A25: =CHOSEN_FISH | C25: =VLOOKUP($A25,$A$30:$E$33,COLUMN(),0) | D25: =VLOOKUP($A25,$A$30:$E$33,COLUMN(),0) | E25: =VLOOKUP($A25,$A$30:$E$33,COLUMN(),0) | F25: =365/C25 | G25: =E25*D25 | H25: =F25*E25*D25
A29: Aquatic
A30: Tilapia | C30: 180 | D30: 100 | E30: 0.6
A31: Trout | C31: 365 | D31: 22 | E31: 0.5
A33: Microorganisms
A34: Bacteria, etc.
A36: Greens | C36: Price ($/kg)
A37: Tomato | C37: 3
A38: Lettuce | B38: Lactuca sativa | C38: 5
A39: Chicória | B39: Cichorium intybus | C39: 10
A40: Almeirão Pão de Açúcar | B40: Cichorium intybus | C40: 10
A41: Almeirão Amargo | B41: Cichorium intybus | C41: 10
A42: Espinafre | B42: Spinacia oleracea | C42: 15
A43: Alface | B43: Lactuca sativa | C43: 5
A44: Salsinha | B44: Petroselinum crispum | C44: 15
A45: Manjericão | B45: Ocimum basilicum | C45: 30
A46: Agrião | B46: Nasturtium officinale | C46: 15
A47: Cebolinha | B47: Allium schoenoprasum | C47: 12
A49: Aquatic | C49: Price ($/kg)
...

Sheet User_Parameters
A1: Location | B1: Votuporanga
A2: Coordinates | B2: São Paulo, Brazil · -20.423°, -49.973°
A3: Data range: 2023-06 → 2026-06
A4: Source | B4: Open-Meteo ERA5 Historical Weather API
A6: Month | B6: Avg High (°C) | C6: Avg Mean (°C) | D6: Avg Low (°C) | E6: Precipitation (mm) | F6: ET₀ (mm) | G6: Water Deficit (mm)
A7: Jan | B7: 31.6 | C7: 26.6 | D7: 21.7 | E7: 122 | F7: 160 | G7: 38.3
A8: Feb | B8: 30.6 | C8: 26.3 | D8: 21.9 | E8: 139 | F8: 149 | G8: 10
A9: Mar | B9: 31.5 | C9: 26.8 | D9: 22 | E9: 117 | F9: 151 | G9: 34
A10: Apr | B10: 30.7 | C10: 25.7 | D10: 20.7 | E10: 71 | F10: 126 | G10: 54.5
A11: May | B11: 28.9 | C11: 23.3 | D11: 17.8 | E11: 14 | F11: 121 | G11: 106.5
A12: Jun | B12: 26.9 | C12: 21.4 | D12: 15.9 | E12: 63 | F12: 113 | G12: 49.3
A13: Jul | B13: 29 | C13: 22.5 | D13: 16.1 | E13: 4 | F13: 127 | G13: 123.5
A14: Aug | B14: 30.9 | C14: 24.2 | D14: 17.4 | E14: 11 | F14: 161 | G14: 149.9
A15: Sep | B15: 34.9 | C15: 28.2 | D15: 21.5 | E15: 42 | F15: 190 | G15: 147.7
A16: Oct | B16: 33.2 | C16: 27.6 | D16: 22 | E16: 107 | F16: 180 | G16: 72.2
A17: Nov | B17: 32.8 | C17: 27.2 | D17: 21.5 | E17: 152 | F17: 179 | G17: 27.1
A18: Dec | B18: 31.9 | C18: 27.2 | D18: 22.4 | E18: 170 | F18: 159 | G18: -10.9
A19: Annual | B19: — | C19: 25.6 | D19: — | E19: 1013 | F19: 1815 | G19: 802.3

Sheet Location_Data
A1: Location | B1: Votuporanga
A2: Coordinates | B2: São Paulo, Brazil · -20.423°, -49.973°
A3: Data range: 2023-06 → 2026-06
A4: Source | B4: Open-Meteo ERA5 Historical Weather API
A6: Month | B6: Avg High (°C) | C6: Avg Mean (°C) | D6: Avg Low (°C) | E6: Precipitation (mm) | F6: ET₀ (mm) | G6: Water Deficit (mm)
A7: Jan | B7: 31.6 | C7: 26.6 | D7: 21.7 | E7: 122 | F7: 160 | G7: 38.3
A8: Feb | B8: 30.6 | C8: 26.3 | D8: 21.9 | E8: 139 | F8: 149 | G8: 10
A9: Mar | B9: 31.5 | C9: 26.8 | D9: 22 | E9: 117 | F9: 151 | G9: 34
A10: Apr | B10: 30.7 | C10: 25.7 | D10: 20.7 | E10: 71 | F10: 126 | G10: 54.5
A11: May | B11: 28.9 | C11: 23.3 | D11: 17.8 | E11: 14 | F11: 121 | G11: 106.5
A12: Jun | B12: 26.9 | C12: 21.4 | D12: 15.9 | E12: 63 | F12: 113 | G12: 49.3
A13: Jul | B13: 29 | C13: 22.5 | D13: 16.1 | E13: 4 | F13: 127 | G13: 123.5
A14: Aug | B14: 30.9 | C14: 24.2 | D14: 17.4 | E14: 11 | F14: 161 | G14: 149.9
A15: Sep | B15: 34.9 | C15: 28.2 | D15: 21.5 | E15: 42 | F15: 190 | G15: 147.7
A16: Oct | B16: 33.2 | C16: 27.6 | D16: 22 | E16: 107 | F16: 180 | G16: 72.2
A17: Nov | B17: 32.8 | C17: 27.2 | D17: 21.5 | E17: 152 | F17: 179 | G17: 27.1
A18: Dec | B18: 31.9 | C18: 27.2 | D18: 22.4 | E18: 170 | F18: 159 | G18: -10.9
A19: Annual | B19: — | C19: 25.6 | D19: — | E19: 1013 | F19: 1815 | G19: 802.3

Sheet Framework
K1: What is the best combination of greens given my equity and available space? | S1: 0 | T1: 1 | U1: 2 | V1: 3 | W1: 4 | X1: 5 | Y1: 6 | Z1: 7 | AA1: 8 | AB1: 9 | AC1: 10
S2: Year 0 | T2: Year 1 | U2: Year 2 | V2: Year 3 | W2: Year 4 | X2: Year 5 | Y2: Year 6 | Z2: Year 7 | AA2: Year 8 | AB2: Year 9 | AC2: Year 10 | AF2: Waterfall
H3: Legend | L3: Constraints | P3: #VALUE! | R3: Gross Revenue (Sales) | S3: 0 | T3: =Revenues!J4 | U3: =M26 | V3: =U3 | W3: =V3 | X3: =W3 | Y3: =X3 | Z3: =Y3 | AA3: =Z3 | AB3: =AA3 | AC3: =AB3 | AE3: Gross Revenue (Sales) | AF3: =AC3
H4: User Input | M4: Model | R4: (-) Sales Taxes | S4: 0 | T4: =Revenues!J5 | U4: =Revenues!K5 | V4: =U4 | W4: =V4 | X4: =W4 | Y4: =X4 | Z4: =Y4 | AA4: =Z4 | AB4: =AA4 | AC4: =AB4 | AE4: Sales Taxes | AF4: =-AC4
H5: Set Parameter | L5: Equity | M5: 10000 | N5: $ | R5: (=) Net Revenue | S5: 0 | T5: =T3-T4 | U5: =U3-U4 | V5: =V3-V4 | W5: =W3-W4 | X5: =X3-X4 | Y5: =Y3-Y4 | Z5: =Z3-Z4 | AA5: =AA3-AA4 | ... AC5: =AC3-AC4 | AE5: Cost of Goods Sold (COGS) | AF5: =-AC6
H6: Constraint (user input) | L6: Area | M6: 1000 | N6: m² | R6: (-) Cost of Goods Sold (COGS) | S6: 0 | T6: =Costs!I22-T8-T9 | U6: =T6 | V6: =U6 | W6: =V6 | X6: =W6 | Y6: =X6 | Z6: =Y6 | AA6: =Z6 | AB6: =AA6 | AC6: =AB6 | AE6: People Costs | AF6: =-AC7
H7: Variables | R7: (-) People Costs | S7: 0 | T7: =E27 | U7: =T7 | V7: =U7 | W7: =V7 | X7: =W7 | Y7: =X7 | Z7: =Y7 | AA7: =Z7 | AB7: =AA7 | AC7: =AB7 | AE7: Water Costs | AF7: =-AC8
H8: Formula (do not change) | R8: (-) Water | S8: 0 | T8: =Costs!D73 | U8: =T8 | V8: =U8 | W8: =V8 | X8: =W8 | Y8: =X8 | Z8: =Y8 | AA8: =Z8 | AB8: =AA8 | AC8: =AB8 | AE8: Energy Costs | AF8: =-AC9
H9: Output | L9: Chosen | M9: Lettuce | R9: (-) Energy | S9: 0 | T9: =Costs!E69 | U9: =T9 | V9: =U9 | W9: =V9 | X9: =W9 | Y9: =X9 | Z9: =Y9 | AA9: =Z9 | AB9: =AA9 | AC9: =AB9 | AE9: Debt Interest | AF9: =-AC11
M10: Tilapia | R10: (=) EBITDA | S10: =S5-SUM(S6:S7) | T10: =T5-SUM(T6:T9) | U10: =U5-SUM(U6:U9) | V10: =V5-SUM(V6:V9) | W10: =W5-SUM(W6:W9) | X10: =X5-SUM(X6:X9) | Y10: =Y5-SUM(Y6:Y9) | Z10: =Z5-SUM(Z6:Z9) | AA10: =AA5-SUM(AA6:AA9) | ... AC10: =AC5-SUM(AC6:AC9) | AE10: Corporate Tax | AF10: =-AC12
M11: South America | R11: (-) Debt Interest | S11: 0 | T11: =Funding!D17 | U11: =Funding!E17 | V11: =Funding!F17 | W11: =Funding!G17 | X11: =Funding!H17 | Y11: =Funding!I17 | Z11: =Funding!J17 | AA11: =Funding!K17 | ... AC11: =Funding!M17 | AE11: Investment | AF11: =-AC13
R12: (-) Corporate Tax | S12: 0 | T12: =MAX(T10*Revenues!$B$12,0) | U12: =MAX(U10*Revenues!$B$12,0) | V12: =MAX(V10*Revenues!$B$12,0) | W12: =MAX(W10*Revenues!$B$12,0) | X12: =MAX(X10*Revenues!$B$12,0) | Y12: =MAX(Y10*Revenues!$B$12,0) | Z12: =MAX(Z10*Revenues!$B$12,0) | AA12: =MAX(AA10*Revenues!$B$12,0) | ... AC12: =MAX(AC10*Revenues!$B$12,0) | AE12: Project financing loan repayment | AF12: =-AC15
R13: (-) Investment (Equity on Y0) | S13: =Funding!C5 | T13: =Investment!L4 | U13: =Investment!M4 | V13: =Investment!N4 | W13: =Investment!O4 | X13: =Investment!P4 | Y13: =Investment!Q4 | Z13: =Investment!R4 | AA13: =Investment!S4 | ... AC13: =Investment!U4 | AE13: FREE CASH FLOW | AF13: =SUM(AF3:AF12)
H14: Is is worth investing in some of the productivity boosters? | R14: (=) CASH FLOW | S14: =S10-S11-S12-S13 | T14: =T10-T11-T12-T13 | U14: =U10-U11-U12-U13 | V14: =V10-V11-V12-V13 | W14: =W10-W11-W12-W13 | X14: =X10-X11-X12-X13 | Y14: =Y10-Y11-Y12-Y13 | Z14: =Z10-Z11-Z12-Z13 | ... AC14: =AC10-AC11-AC12-AC13
H15: Which plant and fish combination is most adequate for my climate? | R15: (-) Project financing loan repayment | S15: 0 | T15: =Funding!D16 | U15: =Funding!E16 | V15: =Funding!F16 | W15: =Funding!G16 | X15: =Funding!H16 | Y15: =Funding!I16 | Z15: =Funding!J16 | AA15: =Funding!K16 | ... AC15: =Funding!M16
H16: Give these greens and fish, what size do I need to make the endeavour commercially viable? | R16: FREE CASH FLOW | S16: =S14-S15 | T16: =T14-T15 | U16: =U14-U15 | V16: =V14-V15 | W16: =W14-W15 | X16: =X14-X15 | Y16: =Y14-Y15 | Z16: =Z14-Z15 | ... AC16: =AC14-AC15
R17: Adjusted value in time | S17: =S16/(1+WACC)^S1 | T17: =T16/(1+WACC)^T1 | U17: =U16/(1+WACC)^U1 | V17: =V16/(1+WACC)^V1 | W17: =W16/(1+WACC)^W1 | X17: =X16/(1+WACC)^X1 | Y17: =Y16/(1+WACC)^Y1 | Z17: =Z16/(1+WACC)^Z1 | ... AC17: =AC16/(1+WACC)^AC1
R18: Accumulated value in time | S18: =SUM($S$17:S17) | T18: =SUM($S$17:T17) | U18: =SUM($S$17:U17) | V18: =SUM($S$17:V17) | W18: =SUM($S$17:W17) | X18: =SUM($S$17:X17) | Y18: =SUM($S$17:Y17) | Z18: =SUM($S$17:Z17) | ... AC18: =SUM($S$17:AC17)
R20: Net Present Value | S20: =S16+NPV(WACC,T16:AC16) | T20: =IF(S20>0,"YES","NO")
B21: Environment
R22: Discounted Payback | S22: {=IFERROR(MATCH(TRUE,S18:AC18>=0,0)-2+ABS(INDEX(S18:AC18,MATCH(TRUE,S18:AC18>=0,0)-1))/(INDEX(S18:AC18,MATCH(TRUE,S18:AC18>=0,0))-INDEX(S18:AC18,MATCH(TRUE,S18:AC18>=0,0)-1)),"Over 10")} | T22: years
B24: Political | C24: Market | F24: #VALUE! | J24: #VALUE! | L24: #VALUE! | M24: #VALUE!
F25: Fish & Others | J25: Greens | L25: Services | M25: Revenue
C26: Channel & Clients | F26: =Revenues!G4 | J26: =Revenues!G6 | L26: =Revenues!G7 | M26: =SUM(F26:L26)
B27: Economic | D27: Value Chain | E27: =Costs!I3
D29: Firm Infrastructure
B30: Social | C30: Price & Promotion | E30: Operations | N30: #VALUE!
D31: Human Resources Mgment | M31: #VALUE! | S31: Temperature adjustment | U31: Equipment Energy consumtpion
F32: Fish Younglings | H32: Biologic Surface Area | J32: Green Younglings | N32: Cash Flow | P32: #VALUE! | S32: =System_Parameters!O43 | T32: kWh/year | U32: =Investment!F5
B33: Technological | D33: Technology | F33: =Costs!E62 | H33: =Costs!C26 | J33: =Costs!E41 | L33: Services | M33: Cost | S33: Water need
C34: Differentiation | F34: Feed | H34: Carbon Source | J34: Substrate | L34: =Costs!C35+SUM(Costs!G41:H41)+SUM(Costs!G62:H62) | M34: =SUM(D27:L43) | N34: =M26-M34 | P34: =S20 | S34: =System_Parameters!O45 | T34: mm/year | U34: =System_Parameters!Q45 | V34: m3/year
D35: Procurement | F35: =Costs!F62 | H35: =Costs!C27 | J35: =Costs!F41 | N35: Average Yearly | P35: =IFERROR(ROUND(S22,1)&" years","Over 10 years")
B36: Legal | H36: Microbiota | J36: Pollinator
D37: Internal Logistics | H37: =Costs!C28 | J37: =Costs!C31
F38: Oxygen | H38: Insects | J38: Nutrients
B39: Environmental | C39: Risk & Substitutes | D39: External Logistics | F39: =Costs!C25 | H39: =Costs!C29 | J39: =Costs!C32
H40: Worms | J40: Carbon Dioxide
D41: Sales & Marketing | H41: =Costs!C30 | J41: =Costs!C33
G42: Water | I42: Controls | K42: Energy
G43: =Costs!D73 | I43: =Costs!C34+Costs!C23 | K43: =Costs!E69
...

Sheet System_Parameters
A1: Parameters
A3: Sizing | N3: Total Area (m2) | O3: Production Area (m2) | P3: Area Hydroponic (m²) | R3: Yearly Gross Production (kg)
A4: Plant-fish mass ratio (PFRM)(Kg/kg) | E4: 3.1 | F4: system produces 3.1 kg of plants for every 1 kg of fish harvested over the same measurement period | N4: =TOTAL_AREA | O4: =N4*(1-E8) | P4: =O4-P8 | Q4: =P4/O4 | R4: =P4*K14
A5: Average tank volume (m³) | E5: 10 | P5: =HYDROPONIC_AREA/E7 | Q5: Hydroponics units
A6: Height tank (m) | E6: 1.2
A7: Max hydroponics system unit size (m²) | E7: 5 | P7: Area RAS (m²)
A8: Administration, Logistics and Service necessary area (%) | E8: 0.15 | P8: =O4/(1+E4*K14/K19) | Q8: =P8/O4 | R8: =P8*K17
P9: Volume RAS (m³)
C10: Life Cycle (days/ organism) | D10: Space occupied (organism /(m²/m³)) | E10: Organism production(kg/organism) | F10: Minimum Temperature ( C) | G10: Maximum Temperature ( C) | H10: Ideal Temperature ( C) | I10: Full renew (changes/ year) | J10: Density (kg/m²) | K10: Space yield (kg/m²) | P10: =P8/E6 | Q10: =ROUND(P8/E5,0) | R10: RAS Tanks
A13: Chosen Greens
A14: =CHOSEN_GREEN | C14: =VLOOKUP($A14,$A$19:$H$30,COLUMN(),0) | D14: =VLOOKUP($A14,$A$19:$H$30,COLUMN(),0) | E14: =VLOOKUP($A14,$A$19:$H$30,COLUMN(),0) | F14: =VLOOKUP($A14,$A$19:$H$30,COLUMN(),0) | G14: =VLOOKUP($A14,$A$19:$H$30,COLUMN(),0) | H14: =VLOOKUP($A14,$A$19:$H$30,COLUMN(),0) | I14: =365/C14 | J14: =E14*D14 | K14: =I14*E14*D14
A16: Chosen Aquatic
A17: =CHOSEN_FISH | C17: =VLOOKUP($A17,$A$33:$H$36,COLUMN(),0) | D17: =VLOOKUP($A17,$A$33:$H$36,COLUMN(),0) | E17: =VLOOKUP($A17,$A$33:$H$36,COLUMN(),0) | F17: =VLOOKUP($A17,$A$33:$H$36,COLUMN(),0) | G17: =VLOOKUP($A17,$A$33:$H$36,COLUMN(),0) | H17: =VLOOKUP($A17,$A$33:$H$36,COLUMN(),0) | I17: =365/C17 | J17: =E17*D17 | K17: =I17*E17*D17
A18: Greens
A19: Tomato | C19: 365 | D19: 3.9 | E19: 10 | F19: 13 | G19: 32 | H19: 23 | I19: =365/C19 | J19: =E19*D19 | K19: =I19*E19*D19
A20: Lettuce | B20: Lactuca sativa | C20: 35 | D20: 25 | E20: 0.2 | F20: 7 | G20: 24 | H20: 18 | I20: =365/C20 | J20: =E20*D20 | K20: =I20*E20*D20
A21: Chicória | B21: Cichorium intybus | C21: 28 | D21: 16 | E21: 0.13232 | F21: 7 | G21: 24 | H21: 18 | I21: =365/C21 | J21: =E21*D21 | K21: =I21*E21*D21
A22: Almeirão Pão de Açúcar | B22: Cichorium intybus | C22: 28 | D22: 16 | E22: 0.09816 | F22: 7 | G22: 24 | H22: 18 | I22: =365/C22 | J22: =E22*D22 | K22: =I22*E22*D22
A23: Almeirão Amargo | B23: Cichorium intybus | C23: 28 | D23: 16 | E23: 0.11576 | F23: 7 | G23: 24 | H23: 18 | I23: =365/C23 | J23: =E23*D23 | K23: =I23*E23*D23
A24: Espinafre | B24: Spinacia oleracea | C24: 28 | D24: 16 | E24: 0.07872 | F24: 7 | G24: 24 | H24: 18 | I24: =365/C24 | J24: =E24*D24 | K24: =I24*E24*D24
A25: Alface | B25: Lactuca sativa | C25: 28 | D25: 16 | E25: 0.07872 | F25: 7 | G25: 24 | H25: 18 | I25: =365/C25 | J25: =E25*D25 | K25: =I25*E25*D25
A26: Salsinha | B26: Petroselinum crispum | C26: 28 | D26: 16 | E26: 0.03587 | F26: 7 | G26: 24 | H26: 18 | I26: =365/C26 | J26: =E26*D26 | K26: =I26*E26*D26
A27: Manjericão | B27: Ocimum basilicum | C27: 28 | D27: 16 | E27: 0.04206 | F27: 7 | G27: 24 | H27: 18 | I27: =365/C27 | J27: =E27*D27 | K27: =I27*E27*D27
A28: Agrião | B28: Nasturtium officinale | C28: 28 | D28: 16 | E28: 0.07369 | F28: 7 | G28: 24 | H28: 18 | I28: =365/C28 | J28: =E28*D28 | K28: =I28*E28*D28
A29: Cebolinha | B29: Allium schoenoprasum | C29: 28 | D29: 16 | E29: 0.02525 | F29: 7 | G29: 24 | H29: 18 | I29: =365/C29 | J29: =E29*D29 | K29: =I29*E29*D29
A32: Aquatic
A33: Tilapia | C33: 180 | D33: 100 | E33: 0.6 | F33: 11 | G33: 35 | H33: 29
A34: Trout | C34: 365 | D34: 22 | E34: 0.5 | F34: 0 | G34: 21 | H34: 14
A36: Microorganisms
A37: Bacteria, etc. | F37: 10 | G37: 49 | H37: 27
A39: SYSTEM CONTROL
A40: Temperature
A41: Tank size (mass in kg) | C41: 1000 | D41: kg of water | E41: Energy to heat | G41: Q=m⋅c⋅ΔT
A42: Water c (specific heat capacity) | C42: 4186 | D42: 𝐽 / ( 𝑘 𝑔 ⋅ 𝐾 ) | O42: Temperature adjustment
A43: U = overall heat transfer coefficient (W/m²·K) | C43: =(5+0.5)/2 | D43: Poor insulation (~5W/m²K) to Good insulation (~0.5W/m²K) | E43: Energy to maintain | G43: P=U⋅A⋅ΔT | O43: =SUM(D71:O72) | P43: kWh/year
A44: COP (if Chiller, etc) | C44: =(2.5+4)/2 | O44: Water need
A45: HEf = heat production (kJ/day) | D45: Biological load of stocking density | G45: HEf=0.04643⋅W0.7882⋅T1.837 | J45: Feed based, O2 based or ignore? | O45: =-SUM(D75:O75) | P45: mm/year | Q45: =O45/1000*O4 | R45: m3/year
A46: Conversion 𝑘𝑊h to 𝐽 | C46: 3600000
A48: Water
A49: Purge percentage (pH control, salts, etc.) | C49: 0.03
...

Sheet Investment
A1: INVESTMENTS
A2: RAS | B2: =System_Parameters!P8 | C2: m²
B3: =System_Parameters!P10 | C3: m³
B4: =System_Parameters!Q10 | C4: tanks | F4: Energy consumption | J4: Total Investment | K4: =SUM(K5:K7) | L4: =SUM(L5:L7) | M4: =SUM(M5:M7) | N4: =SUM(N5:N7) | O4: =SUM(O5:O7) | P4: =SUM(P5:P7) | Q4: =SUM(Q5:Q7) | R4: =SUM(R5:R7) | ... U4: =SUM(U5:U7)
A5: Hydroponics | B5: =System_Parameters!P4 | C5: m² | F5: =SUMPRODUCT(F11:F74,C11:C74) | K5: =K9+K33+K49+K64+K73 | L5: =L9+L33+L49 | M5: =M9+M33+M49 | N5: =N9+N33+N49 | O5: =O9+O33+O49 | P5: =P9+P33+P49 | Q5: =Q9+Q33+Q49 | R5: =R9+R33+R49 | S5: =S9+S33+S49 | ... U5: =U9+U33+U49
A6: Maintenance Cost | B6: 0.01 | J6: Maintenance | K6: =MAINTENANCE_PERCENTAGE*K5 | L6: =MAINTENANCE_PERCENTAGE*L5 | M6: =MAINTENANCE_PERCENTAGE*M5 | N6: =MAINTENANCE_PERCENTAGE*N5 | O6: =MAINTENANCE_PERCENTAGE*O5 | P6: =MAINTENANCE_PERCENTAGE*P5 | Q6: =MAINTENANCE_PERCENTAGE*Q5 | R6: =MAINTENANCE_PERCENTAGE*R5 | ... U6: =MAINTENANCE_PERCENTAGE*U5
A7: Spare Parts Costs | B7: 0.025 | G7: System productivity Factor | H7: =MAX(H10:H74) | J7: Spare parts | K7: =($I9*K9+$I33*K33+$I49*K49)*PARTS_PERCENTAGE | L7: =($I9*L9+$I33*L33+$I49*L49)*PARTS_PERCENTAGE | M7: =($I9*M9+$I33*M33+$I49*M49)*PARTS_PERCENTAGE | N7: =($I9*N9+$I33*N33+$I49*N49)*PARTS_PERCENTAGE | O7: =($I9*O9+$I33*O33+$I49*O49)*PARTS_PERCENTAGE | P7: =($I9*P9+$I33*P33+$I49*P49)*PARTS_PERCENTAGE | Q7: =($I9*Q9+$I33*Q33+$I49*Q49)*PARTS_PERCENTAGE | R7: =($I9*R9+$I33*R33+$I49*R49)*PARTS_PERCENTAGE | ... U7: =($I9*U9+$I33*U33+$I49*U49)*PARTS_PERCENTAGE
A8: Equipment | B8: Cost | C8: User Choice | D8: Life-Span (years) | E8: Power (W) | F8: kWh/year | G8: Productivity Factor | H8: Activated Productivity? | I8: Spare Parts? | J8: Year | K8: 0 | L8: 1 | M8: 2 | N8: 3 | O8: 4 | P8: 5 | Q8: 6 | R8: 7 | S8: 8 | T8: 9 | U8: 10
A9: Recirculating Aquaculture System (RAS) | I9: =SUMPRODUCT(C11:C31,I11:I31)/SUM(C11:C31) | K9: =K10+K22 | L9: =L10+L22 | M9: =M10+M22 | N9: =N10+N22 | O9: =O10+O22 | P9: =P10+P22 | Q9: =Q10+Q22 | R9: =R10+R22 | ... U9: =U10+U22
A10: 1/RAS enclosure | K10: =SUM(K11:K21) | L10: =SUM(L11:L21) | M10: =SUM(M11:M21) | N10: =SUM(N11:N21) | O10: =SUM(O11:O21) | P10: =SUM(P11:P21) | Q10: =SUM(Q11:Q21) | R10: =SUM(R11:R21) | ... U10: =SUM(U11:U21)
A11: Biofilter | B11: 100 | C11: 1 | D11: 10 | I11: 0 | K11: =(MOD(K$8,$D11)=0)*$B11*$C11 | L11: =(MOD(L$8,$D11)=0)*$B11*$C11 | M11: =(MOD(M$8,$D11)=0)*$B11*$C11 | N11: =(MOD(N$8,$D11)=0)*$B11*$C11 | O11: =(MOD(O$8,$D11)=0)*$B11*$C11 | P11: =(MOD(P$8,$D11)=0)*$B11*$C11 | Q11: =(MOD(Q$8,$D11)=0)*$B11*$C11 | R11: =(MOD(R$8,$D11)=0)*$B11*$C11 | ... U11: =(MOD(U$8,$D11)=0)*$B11*$C11
A12: Sump | B12: 100 | C12: 1 | D12: 5 | I12: 0 | K12: =(MOD(K$8,$D12)=0)*$B12*$C12 | L12: =(MOD(L$8,$D12)=0)*$B12*$C12 | M12: =(MOD(M$8,$D12)=0)*$B12*$C12 | N12: =(MOD(N$8,$D12)=0)*$B12*$C12 | O12: =(MOD(O$8,$D12)=0)*$B12*$C12 | P12: =(MOD(P$8,$D12)=0)*$B12*$C12 | Q12: =(MOD(Q$8,$D12)=0)*$B12*$C12 | R12: =(MOD(R$8,$D12)=0)*$B12*$C12 | ... U12: =(MOD(U$8,$D12)=0)*$B12*$C12
A13: Pump | B13: 100 | C13: 1 | D13: 5 | I13: 1 | K13: =(MOD(K$8,$D13)=0)*$B13*$C13 | L13: =(MOD(L$8,$D13)=0)*$B13*$C13 | M13: =(MOD(M$8,$D13)=0)*$B13*$C13 | N13: =(MOD(N$8,$D13)=0)*$B13*$C13 | O13: =(MOD(O$8,$D13)=0)*$B13*$C13 | P13: =(MOD(P$8,$D13)=0)*$B13*$C13 | Q13: =(MOD(Q$8,$D13)=0)*$B13*$C13 | R13: =(MOD(R$8,$D13)=0)*$B13*$C13 | ... U13: =(MOD(U$8,$D13)=0)*$B13*$C13
A14: Gas Exchange | C14: 1 | D14: 5 | H14: =C14*G14 | I14: 1 | K14: =(MOD(K$8,$D14)=0)*$B14*$C14 | L14: =(MOD(L$8,$D14)=0)*$B14*$C14 | M14: =(MOD(M$8,$D14)=0)*$B14*$C14 | N14: =(MOD(N$8,$D14)=0)*$B14*$C14 | O14: =(MOD(O$8,$D14)=0)*$B14*$C14 | P14: =(MOD(P$8,$D14)=0)*$B14*$C14 | Q14: =(MOD(Q$8,$D14)=0)*$B14*$C14 | R14: =(MOD(R$8,$D14)=0)*$B14*$C14 | ... U14: =(MOD(U$8,$D14)=0)*$B14*$C14
A15: Purging Tank "Off-Flavor" | C15: 0 | D15: 10 | H15: =C15*G15 | I15: 0 | K15: =(MOD(K$8,$D15)=0)*$B15*$C15 | L15: =(MOD(L$8,$D15)=0)*$B15*$C15 | M15: =(MOD(M$8,$D15)=0)*$B15*$C15 | N15: =(MOD(N$8,$D15)=0)*$B15*$C15 | O15: =(MOD(O$8,$D15)=0)*$B15*$C15 | P15: =(MOD(P$8,$D15)=0)*$B15*$C15 | Q15: =(MOD(Q$8,$D15)=0)*$B15*$C15 | R15: =(MOD(R$8,$D15)=0)*$B15*$C15 | ... U15: =(MOD(U$8,$D15)=0)*$B15*$C15
A16: Denitrification (USBR) | C16: 0 | D16: 20 | H16: =C16*G16 | I16: 0 | K16: =(MOD(K$8,$D16)=0)*$B16*$C16 | L16: =(MOD(L$8,$D16)=0)*$B16*$C16 | M16: =(MOD(M$8,$D16)=0)*$B16*$C16 | N16: =(MOD(N$8,$D16)=0)*$B16*$C16 | O16: =(MOD(O$8,$D16)=0)*$B16*$C16 | P16: =(MOD(P$8,$D16)=0)*$B16*$C16 | Q16: =(MOD(Q$8,$D16)=0)*$B16*$C16 | R16: =(MOD(R$8,$D16)=0)*$B16*$C16 | ... U16: =(MOD(U$8,$D16)=0)*$B16*$C16
A17: Drum Filter | C17: 0 | D17: 5 | H17: =C17*G17 | I17: 0 | K17: =(MOD(K$8,$D17)=0)*$B17*$C17 | L17: =(MOD(L$8,$D17)=0)*$B17*$C17 | M17: =(MOD(M$8,$D17)=0)*$B17*$C17 | N17: =(MOD(N$8,$D17)=0)*$B17*$C17 | O17: =(MOD(O$8,$D17)=0)*$B17*$C17 | P17: =(MOD(P$8,$D17)=0)*$B17*$C17 | Q17: =(MOD(Q$8,$D17)=0)*$B17*$C17 | R17: =(MOD(R$8,$D17)=0)*$B17*$C17 | ... U17: =(MOD(U$8,$D17)=0)*$B17*$C17
A18: UV-sterilization | C18: 0 | D18: 5 | H18: =C18*G18 | I18: 0 | K18: =(MOD(K$8,$D18)=0)*$B18*$C18 | L18: =(MOD(L$8,$D18)=0)*$B18*$C18 | M18: =(MOD(M$8,$D18)=0)*$B18*$C18 | N18: =(MOD(N$8,$D18)=0)*$B18*$C18 | O18: =(MOD(O$8,$D18)=0)*$B18*$C18 | P18: =(MOD(P$8,$D18)=0)*$B18*$C18 | Q18: =(MOD(Q$8,$D18)=0)*$B18*$C18 | R18: =(MOD(R$8,$D18)=0)*$B18*$C18 | ... U18: =(MOD(U$8,$D18)=0)*$B18*$C18
A19: Oxygen enrichment | C19: 0 | D19: 5 | E19: 100 | F19: =E19*RAS_VOLUME*24*365/1000 | H19: =C19*G19 | I19: 0 | K19: =(MOD(K$8,$D19)=0)*$B19*$C19 | L19: =(MOD(L$8,$D19)=0)*$B19*$C19 | M19: =(MOD(M$8,$D19)=0)*$B19*$C19 | N19: =(MOD(N$8,$D19)=0)*$B19*$C19 | O19: =(MOD(O$8,$D19)=0)*$B19*$C19 | P19: =(MOD(P$8,$D19)=0)*$B19*$C19 | Q19: =(MOD(Q$8,$D19)=0)*$B19*$C19 | R19: =(MOD(R$8,$D19)=0)*$B19*$C19 | ... U19: =(MOD(U$8,$D19)=0)*$B19*$C19
A20: Ozone enrighment | C20: 0 | D20: 5 | E20: 12 | F20: =E20*RAS_VOLUME*12*365/1000 | H20: =C20*G20 | I20: 0 | K20: =(MOD(K$8,$D20)=0)*$B20*$C20 | L20: =(MOD(L$8,$D20)=0)*$B20*$C20 | M20: =(MOD(M$8,$D20)=0)*$B20*$C20 | N20: =(MOD(N$8,$D20)=0)*$B20*$C20 | O20: =(MOD(O$8,$D20)=0)*$B20*$C20 | P20: =(MOD(P$8,$D20)=0)*$B20*$C20 | Q20: =(MOD(Q$8,$D20)=0)*$B20*$C20 | R20: =(MOD(R$8,$D20)=0)*$B20*$C20 | ... U20: =(MOD(U$8,$D20)=0)*$B20*$C20
A21: Heat Exchanger | C21: 0 | D21: 3 | E21: 200 | F21: =E21*RAS_VOLUME*4*365/1000 | H21: =C21*G21 | I21: 1 | K21: =(MOD(K$8,$D21)=0)*$B21*$C21 | L21: =(MOD(L$8,$D21)=0)*$B21*$C21 | M21: =(MOD(M$8,$D21)=0)*$B21*$C21 | N21: =(MOD(N$8,$D21)=0)*$B21*$C21 | O21: =(MOD(O$8,$D21)=0)*$B21*$C21 | P21: =(MOD(P$8,$D21)=0)*$B21*$C21 | Q21: =(MOD(Q$8,$D21)=0)*$B21*$C21 | R21: =(MOD(R$8,$D21)=0)*$B21*$C21 | ... U21: =(MOD(U$8,$D21)=0)*$B21*$C21
A22: 1/fish tank | B22: =FISH_TANK | K22: =SUM(K23:K29) | L22: =SUM(L23:L29) | M22: =SUM(M23:M29) | N22: =SUM(N23:N29) | O22: =SUM(O23:O29) | P22: =SUM(P23:P29) | Q22: =SUM(Q23:Q29) | R22: =SUM(R23:R29) | ... U22: =SUM(U23:U29)
A23: Fish Tank | B23: 500 | C23: 1 | D23: 20 | I23: 0 | K23: =(MOD(K$8,$D23)=0)*$B23*$B$4*FISH_TANK*$C23 | L23: =(MOD(L$8,$D23)=0)*$B23*$B$4*FISH_TANK*$C23 | M23: =(MOD(M$8,$D23)=0)*$B23*$B$4*FISH_TANK*$C23 | N23: =(MOD(N$8,$D23)=0)*$B23*$B$4*FISH_TANK*$C23 | O23: =(MOD(O$8,$D23)=0)*$B23*$B$4*FISH_TANK*$C23 | P23: =(MOD(P$8,$D23)=0)*$B23*$B$4*FISH_TANK*$C23 | Q23: =(MOD(Q$8,$D23)=0)*$B23*$B$4*FISH_TANK*$C23 | R23: =(MOD(R$8,$D23)=0)*$B23*$B$4*FISH_TANK*$C23 | ... U23: =(MOD(U$8,$D23)=0)*$B23*$B$4*FISH_TANK*$C23
A24: pH sensor | B24: 50 | C24: 1 | D24: 1 | I24: 1 | K24: =(MOD(K$8,$D24)=0)*$B24*$B$4*FISH_TANK*$C24 | L24: =(MOD(L$8,$D24)=0)*$B24*$B$4*FISH_TANK*$C24 | M24: =(MOD(M$8,$D24)=0)*$B24*$B$4*FISH_TANK*$C24 | N24: =(MOD(N$8,$D24)=0)*$B24*$B$4*FISH_TANK*$C24 | O24: =(MOD(O$8,$D24)=0)*$B24*$B$4*FISH_TANK*$C24 | P24: =(MOD(P$8,$D24)=0)*$B24*$B$4*FISH_TANK*$C24 | Q24: =(MOD(Q$8,$D24)=0)*$B24*$B$4*FISH_TANK*$C24 | R24: =(MOD(R$8,$D24)=0)*$B24*$B$4*FISH_TANK*$C24 | ... U24: =(MOD(U$8,$D24)=0)*$B24*$B$4*FISH_TANK*$C24
A25: Aeration Pump | B25: 15 | C25: 0 | D25: 5 | E25: 20 | F25: =E25*RAS_VOLUME*24*365/1000 | G25: 1.05 | H25: =C25*G25 | I25: 1 | K25: =(MOD(K$8,$D25)=0)*$B25*$B$4*FISH_TANK*$C25 | L25: =(MOD(L$8,$D25)=0)*$B25*$B$4*FISH_TANK*$C25 | M25: =(MOD(M$8,$D25)=0)*$B25*$B$4*FISH_TANK*$C25 | N25: =(MOD(N$8,$D25)=0)*$B25*$B$4*FISH_TANK*$C25 | O25: =(MOD(O$8,$D25)=0)*$B25*$B$4*FISH_TANK*$C25 | P25: =(MOD(P$8,$D25)=0)*$B25*$B$4*FISH_TANK*$C25 | Q25: =(MOD(Q$8,$D25)=0)*$B25*$B$4*FISH_TANK*$C25 | R25: =(MOD(R$8,$D25)=0)*$B25*$B$4*FISH_TANK*$C25 | ... U25: =(MOD(U$8,$D25)=0)*$B25*$B$4*FISH_TANK*$C25
A26: TAN sensor | C26: 0 | D26: 5 | H26: =C26*G26 | I26: 1 | K26: =(MOD(K$8,$D26)=0)*$B26*$B$4*FISH_TANK*$C26 | L26: =(MOD(L$8,$D26)=0)*$B26*$B$4*FISH_TANK*$C26 | M26: =(MOD(M$8,$D26)=0)*$B26*$B$4*FISH_TANK*$C26 | N26: =(MOD(N$8,$D26)=0)*$B26*$B$4*FISH_TANK*$C26 | O26: =(MOD(O$8,$D26)=0)*$B26*$B$4*FISH_TANK*$C26 | P26: =(MOD(P$8,$D26)=0)*$B26*$B$4*FISH_TANK*$C26 | Q26: =(MOD(Q$8,$D26)=0)*$B26*$B$4*FISH_TANK*$C26 | R26: =(MOD(R$8,$D26)=0)*$B26*$B$4*FISH_TANK*$C26 | ... U26: =(MOD(U$8,$D26)=0)*$B26*$B$4*FISH_TANK*$C26
A27: DO sensor | C27: 0 | D27: 1 | H27: =C27*G27 | I27: 1 | K27: =(MOD(K$8,$D27)=0)*$B27*$B$4*FISH_TANK*$C27 | L27: =(MOD(L$8,$D27)=0)*$B27*$B$4*FISH_TANK*$C27 | M27: =(MOD(M$8,$D27)=0)*$B27*$B$4*FISH_TANK*$C27 | N27: =(MOD(N$8,$D27)=0)*$B27*$B$4*FISH_TANK*$C27 | O27: =(MOD(O$8,$D27)=0)*$B27*$B$4*FISH_TANK*$C27 | P27: =(MOD(P$8,$D27)=0)*$B27*$B$4*FISH_TANK*$C27 | Q27: =(MOD(Q$8,$D27)=0)*$B27*$B$4*FISH_TANK*$C27 | R27: =(MOD(R$8,$D27)=0)*$B27*$B$4*FISH_TANK*$C27 | ... U27: =(MOD(U$8,$D27)=0)*$B27*$B$4*FISH_TANK*$C27
A28: EC sensor | C28: 0 | D28: 1 | H28: =C28*G28 | I28: 1 | K28: =(MOD(K$8,$D28)=0)*$B28*$B$4*FISH_TANK*$C28 | L28: =(MOD(L$8,$D28)=0)*$B28*$B$4*FISH_TANK*$C28 | M28: =(MOD(M$8,$D28)=0)*$B28*$B$4*FISH_TANK*$C28 | N28: =(MOD(N$8,$D28)=0)*$B28*$B$4*FISH_TANK*$C28 | O28: =(MOD(O$8,$D28)=0)*$B28*$B$4*FISH_TANK*$C28 | P28: =(MOD(P$8,$D28)=0)*$B28*$B$4*FISH_TANK*$C28 | Q28: =(MOD(Q$8,$D28)=0)*$B28*$B$4*FISH_TANK*$C28 | R28: =(MOD(R$8,$D28)=0)*$B28*$B$4*FISH_TANK*$C28 | ... U28: =(MOD(U$8,$D28)=0)*$B28*$B$4*FISH_TANK*$C28
A29: Thermometer | C29: 0 | D29: 1 | H29: =C29*G29 | I29: 1 | K29: =(MOD(K$8,$D29)=0)*$B29*$B$4*FISH_TANK*$C29 | L29: =(MOD(L$8,$D29)=0)*$B29*$B$4*FISH_TANK*$C29 | M29: =(MOD(M$8,$D29)=0)*$B29*$B$4*FISH_TANK*$C29 | N29: =(MOD(N$8,$D29)=0)*$B29*$B$4*FISH_TANK*$C29 | O29: =(MOD(O$8,$D29)=0)*$B29*$B$4*FISH_TANK*$C29 | P29: =(MOD(P$8,$D29)=0)*$B29*$B$4*FISH_TANK*$C29 | Q29: =(MOD(Q$8,$D29)=0)*$B29*$B$4*FISH_TANK*$C29 | R29: =(MOD(R$8,$D29)=0)*$B29*$B$4*FISH_TANK*$C29 | ... U29: =(MOD(U$8,$D29)=0)*$B29*$B$4*FISH_TANK*$C29
A30: Automatic Feeder | C30: 0 | D30: 5 | H30: =C30*G30 | I30: 1 | K30: =(MOD(K$8,$D30)=0)*$B30*$B$4*FISH_TANK*$C30 | L30: =(MOD(L$8,$D30)=0)*$B30*$B$4*FISH_TANK*$C30 | M30: =(MOD(M$8,$D30)=0)*$B30*$B$4*FISH_TANK*$C30 | N30: =(MOD(N$8,$D30)=0)*$B30*$B$4*FISH_TANK*$C30 | O30: =(MOD(O$8,$D30)=0)*$B30*$B$4*FISH_TANK*$C30 | P30: =(MOD(P$8,$D30)=0)*$B30*$B$4*FISH_TANK*$C30 | Q30: =(MOD(Q$8,$D30)=0)*$B30*$B$4*FISH_TANK*$C30 | R30: =(MOD(R$8,$D30)=0)*$B30*$B$4*FISH_TANK*$C30 | ... U30: =(MOD(U$8,$D30)=0)*$B30*$B$4*FISH_TANK*$C30
A31: Fish-pump (or escalator) | C31: 0 | D31: 5 | H31: =C31*G31 | I31: 1 | K31: =(MOD(K$8,$D31)=0)*$B31*$B$4*FISH_TANK*$C31 | L31: =(MOD(L$8,$D31)=0)*$B31*$B$4*FISH_TANK*$C31 | M31: =(MOD(M$8,$D31)=0)*$B31*$B$4*FISH_TANK*$C31 | N31: =(MOD(N$8,$D31)=0)*$B31*$B$4*FISH_TANK*$C31 | O31: =(MOD(O$8,$D31)=0)*$B31*$B$4*FISH_TANK*$C31 | P31: =(MOD(P$8,$D31)=0)*$B31*$B$4*FISH_TANK*$C31 | Q31: =(MOD(Q$8,$D31)=0)*$B31*$B$4*FISH_TANK*$C31 | R31: =(MOD(R$8,$D31)=0)*$B31*$B$4*FISH_TANK*$C31 | ... U31: =(MOD(U$8,$D31)=0)*$B31*$B$4*FISH_TANK*$C31
A33: Hydroponics System | I33: =SUMPRODUCT(C35:C48,I35:I48)/SUM(C35:C48) | K33: =K34+K39 | L33: =L34+L39 | M33: =M34+M39 | N33: =N34+N39 | O33: =O34+O39 | P33: =P34+P39 | Q33: =Q34+Q39 | R33: =R34+R39 | ... U33: =U34+U39
A34: 1/Hydroponics m² | B34: =HYDROPONIC_AREA | K34: =SUM(K35:K38) | L34: =SUM(L35:L38) | M34: =SUM(M35:M38) | N34: =SUM(N35:N38) | O34: =SUM(O35:O38) | P34: =SUM(P35:P38) | Q34: =SUM(Q35:Q38) | R34: =SUM(R35:R38) | ... U34: =SUM(U35:U38)
A35: Ventilators | B35: 15 | C35: 1 | D35: 20 | E35: 7 | F35: =E35*HYDROPONIC_AREA*12*365/1000 | G35: 1 | H35: =C35*G35 | I35: 0 | K35: =(MOD(K$8,$D35)=0)*$B35*$C35*HYDROPONIC_AREA | L35: =(MOD(L$8,$D35)=0)*$B35*$C35*HYDROPONIC_AREA | M35: =(MOD(M$8,$D35)=0)*$B35*$C35*HYDROPONIC_AREA | N35: =(MOD(N$8,$D35)=0)*$B35*$C35*HYDROPONIC_AREA | O35: =(MOD(O$8,$D35)=0)*$B35*$C35*HYDROPONIC_AREA | P35: =(MOD(P$8,$D35)=0)*$B35*$C35*HYDROPONIC_AREA | Q35: =(MOD(Q$8,$D35)=0)*$B35*$C35*HYDROPONIC_AREA | R35: =(MOD(R$8,$D35)=0)*$B35*$C35*HYDROPONIC_AREA | ... U35: =(MOD(U$8,$D35)=0)*$B35*$C35*HYDROPONIC_AREA
A36: De-humidifier | B36: 10 | C36: 1 | D36: 10 | E36: 20 | F36: =E36*HYDROPONIC_AREA*8*365/1000 | G36: 1 | H36: =C36*G36 | I36: 0 | K36: =(MOD(K$8,$D36)=0)*$B36*$C36*HYDROPONIC_AREA | L36: =(MOD(L$8,$D36)=0)*$B36*$C36*HYDROPONIC_AREA | M36: =(MOD(M$8,$D36)=0)*$B36*$C36*HYDROPONIC_AREA | N36: =(MOD(N$8,$D36)=0)*$B36*$C36*HYDROPONIC_AREA | O36: =(MOD(O$8,$D36)=0)*$B36*$C36*HYDROPONIC_AREA | P36: =(MOD(P$8,$D36)=0)*$B36*$C36*HYDROPONIC_AREA | Q36: =(MOD(Q$8,$D36)=0)*$B36*$C36*HYDROPONIC_AREA | R36: =(MOD(R$8,$D36)=0)*$B36*$C36*HYDROPONIC_AREA | ... U36: =(MOD(U$8,$D36)=0)*$B36*$C36*HYDROPONIC_AREA
A37: Greenhouse | B37: 15 | C37: 0 | D37: 10 | G37: 1.05 | H37: =C37*G37 | I37: 0 | K37: =(MOD(K$8,$D37)=0)*$B37*$C37*HYDROPONIC_AREA | L37: =(MOD(L$8,$D37)=0)*$B37*$C37*HYDROPONIC_AREA | M37: =(MOD(M$8,$D37)=0)*$B37*$C37*HYDROPONIC_AREA | N37: =(MOD(N$8,$D37)=0)*$B37*$C37*HYDROPONIC_AREA | O37: =(MOD(O$8,$D37)=0)*$B37*$C37*HYDROPONIC_AREA | P37: =(MOD(P$8,$D37)=0)*$B37*$C37*HYDROPONIC_AREA | Q37: =(MOD(Q$8,$D37)=0)*$B37*$C37*HYDROPONIC_AREA | R37: =(MOD(R$8,$D37)=0)*$B37*$C37*HYDROPONIC_AREA | ... U37: =(MOD(U$8,$D37)=0)*$B37*$C37*HYDROPONIC_AREA
A38: Lighting | B38: 20 | C38: 0 | D38: 5 | E38: 100 | F38: =E38*HYDROPONIC_AREA*12*365/1000 | G38: 0.98 | H38: =C38*G38 | I38: 1 | K38: =(MOD(K$8,$D38)=0)*$B38*$C38*HYDROPONIC_AREA | L38: =(MOD(L$8,$D38)=0)*$B38*$C38*HYDROPONIC_AREA | M38: =(MOD(M$8,$D38)=0)*$B38*$C38*HYDROPONIC_AREA | N38: =(MOD(N$8,$D38)=0)*$B38*$C38*HYDROPONIC_AREA | O38: =(MOD(O$8,$D38)=0)*$B38*$C38*HYDROPONIC_AREA | P38: =(MOD(P$8,$D38)=0)*$B38*$C38*HYDROPONIC_AREA | Q38: =(MOD(Q$8,$D38)=0)*$B38*$C38*HYDROPONIC_AREA | R38: =(MOD(R$8,$D38)=0)*$B38*$C38*HYDROPONIC_AREA | ... U38: =(MOD(U$8,$D38)=0)*$B38*$C38*HYDROPONIC_AREA
A39: 1/System unit | B39: =HYDROPONICS_UNIT | K39: =SUM(K40:K47) | L39: =SUM(L40:L47) | M39: =SUM(M40:M47) | N39: =SUM(N40:N47) | O39: =SUM(O40:O47) | P39: =SUM(P40:P47) | Q39: =SUM(Q40:Q47) | R39: =SUM(R40:R47) | ... U39: =SUM(U40:U47)
A40: Sump | B40: 15 | C40: 1 | D40: 5 | I40: 0 | K40: =(MOD(K$8,$D40)=0)*$B40*$C40*HYDROPONICS_UNIT | L40: =(MOD(L$8,$D40)=0)*$B40*$C40*HYDROPONICS_UNIT | M40: =(MOD(M$8,$D40)=0)*$B40*$C40*HYDROPONICS_UNIT | N40: =(MOD(N$8,$D40)=0)*$B40*$C40*HYDROPONICS_UNIT | O40: =(MOD(O$8,$D40)=0)*$B40*$C40*HYDROPONICS_UNIT | P40: =(MOD(P$8,$D40)=0)*$B40*$C40*HYDROPONICS_UNIT | Q40: =(MOD(Q$8,$D40)=0)*$B40*$C40*HYDROPONICS_UNIT | R40: =(MOD(R$8,$D40)=0)*$B40*$C40*HYDROPONICS_UNIT | ... U40: =(MOD(U$8,$D40)=0)*$B40*$C40*HYDROPONICS_UNIT
A41: Pump | B41: 15 | C41: 1 | D41: 3 | I41: 1 | K41: =(MOD(K$8,$D41)=0)*$B41*$C41*HYDROPONICS_UNIT | L41: =(MOD(L$8,$D41)=0)*$B41*$C41*HYDROPONICS_UNIT | M41: =(MOD(M$8,$D41)=0)*$B41*$C41*HYDROPONICS_UNIT | N41: =(MOD(N$8,$D41)=0)*$B41*$C41*HYDROPONICS_UNIT | O41: =(MOD(O$8,$D41)=0)*$B41*$C41*HYDROPONICS_UNIT | P41: =(MOD(P$8,$D41)=0)*$B41*$C41*HYDROPONICS_UNIT | Q41: =(MOD(Q$8,$D41)=0)*$B41*$C41*HYDROPONICS_UNIT | R41: =(MOD(R$8,$D41)=0)*$B41*$C41*HYDROPONICS_UNIT | ... U41: =(MOD(U$8,$D41)=0)*$B41*$C41*HYDROPONICS_UNIT
...

Sheet Funding
A1: FUNDING
J2: Rate
A3: Necessary Initial Investment | C3: =Investment!K4 | H3: Cost of equity | I3: =B5 | J3: =D5 | K3: =$C$3*I3 | L3: =J3*I3
D4: Cost of Capital | H4: Cost of debt | I4: =B8 | J4: =D8 | K4: =$C$3*I4 | L4: =J4*I4
A5: Equity | B5: =C5/C3 | C5: =Framework!M5 | D5: 0.171 | K5: WACC | L5: =SUM(L3:L4)
D6: Years
D7: Yearly Interest Rate | E7: Grace Period | F7: Term | G7: Principal
A8: Debt | B8: =1-B5 | C8: =B8*C3 | D8: 0.1186 | E8: 0 | F8: 10 | G8: =C8/(F8-E8)
B11: Debt repayment and interest schedule | L11: Total Interest Payment | M11: =SUM(D17:M17)
B13: Year | C13: 0 | D13: 1 | E13: 2 | F13: 3 | G13: 4 | H13: 5 | I13: 6 | J13: 7 | K13: 8 | L13: 9 | M13: 10
B14: Period Beginning Balance | C14: =C8 | D14: =C14 | E14: =D18 | F14: =E18 | G14: =F18 | H14: =G18 | I14: =H18 | J14: =I18 | K14: =J18 | L14: =K18 | M14: =L18
B15: Principal Repayment | D15: =IF(D14=0,,IF(D13<=$E$8,0,$G$8)) | E15: =IF(E14=0,,IF(E13<=$E$8,0,$G$8)) | F15: =IF(F14=0,,IF(F13<=$E$8,0,$G$8)) | G15: =IF(G14=0,,IF(G13<=$E$8,0,$G$8)) | H15: =IF(H14=0,,IF(H13<=$E$8,0,$G$8)) | I15: =IF(I14=0,,IF(I13<=$E$8,0,$G$8)) | J15: =IF(J14=0,,IF(J13<=$E$8,0,$G$8)) | K15: =IF(K14=0,,IF(K13<=$E$8,0,$G$8)) | ... M15: =IF(M14=0,,IF(M13<=$E$8,0,$G$8))
B16: Total Payment | D16: =D15+D17 | E16: =E15+E17 | F16: =F15+F17 | G16: =G15+G17 | H16: =H15+H17 | I16: =I15+I17 | J16: =J15+J17 | K16: =K15+K17 | ... M16: =M15+M17
B17: Interest Payment | D17: =D14*$D$8 | E17: =E14*$D$8 | F17: =F14*$D$8 | G17: =G14*$D$8 | H17: =H14*$D$8 | I17: =I14*$D$8 | J17: =J14*$D$8 | K17: =K14*$D$8 | ... M17: =M14*$D$8
B18: Ending Balance | D18: =IF(D14-D15<0,0,D14-D15) | E18: =IF(E14-E15<0,0,E14-E15) | F18: =IF(F14-F15<0,0,F14-F15) | G18: =IF(G14-G15<0,0,G14-G15) | H18: =IF(H14-H15<0,0,H14-H15) | I18: =IF(I14-I15<0,0,I14-I15) | J18: =IF(J14-J15<0,0,J14-J15) | K18: =IF(K14-K15<0,0,K14-K15) | ... M18: =IF(M14-M15<0,0,M14-M15)

Sheet Revenues
A1: Revenues
A3: Chosen Greens | B3: Yearly Standard Gross Production (kg) | C3: Price ($/kg) | D3: Productivity factor | G3: Yearly Revenue | I3: Yearly | J3: Year 1 | K3: Year 2+
A4: =CHOSEN_GREEN | B4: =YEAR_GREEN_PRODUCTION | C4: =VLOOKUP(A4,$A$17:$C$31,3,0) | D4: =PRODUCTIVITY_FACTOR | F4: Greens | G4: =B4*(1-B8)*C4*(1+D4) | I4: Revenue | J4: =(G4+G6)*B10 | K4: =G4+G6
A5: Chosen Aquatic | I5: Sales Tax | J5: =J4*B11 | K5: =K4*B11
A6: =CHOSEN_FISH | B6: =YEAR_FISH_PRODUCTION | C6: =VLOOKUP(A6,$A$17:$C$31,3,0) | F6: Fish | G6: =B6*(1-B9)*C6
F7: Services | G7: =B13+B14
A8: Average Plant loss | B8: 0.05
A9: Average Fish loss | B9: 0.05
A10: First year sales ramp | B10: 0.6 | C10: Bacteria, fish growth, system adjustment
A11: Sales Tax | B11: 0.065
A12: Corporate Tax | B12: 0.15
A13: Service Revenue | B13: 0 | C13: Not focus
A14: Biogas (UASG, EGSB) | B14: 0 | C14: Not focus
A16: Greens | C16: Price ($/kg)
A17: Tomato | C17: 3
A18: Lettuce | B18: Lactuca sativa | C18: 5
A19: Chicória | B19: Cichorium intybus | C19: 10
A20: Almeirão Pão de Açúcar | B20: Cichorium intybus | C20: 10
A21: Almeirão Amargo | B21: Cichorium intybus | C21: 10
A22: Espinafre | B22: Spinacia oleracea | C22: 15
A23: Alface | B23: Lactuca sativa | C23: 5
A24: Salsinha | B24: Petroselinum crispum | C24: 15
A25: Manjericão | B25: Ocimum basilicum | C25: 30
A26: Agrião | B26: Nasturtium officinale | C26: 15
A27: Cebolinha | B27: Allium schoenoprasum | C27: 12
A29: Aquatic | C29: Price ($/kg)
A30: Tilapia | C30: 10
A31: Trout | C31: 15

Sheet Costs
A1: COSTS
A3: Value Chain | I3: =SUMPRODUCT(B5:B17,D5:D17)
A4: People | B4: Net Salary | C4: Unit | D4: Worked time | E4: Unit
A5: General Manager | B5: 10000 | C5: $/month | D5: 12 | E5: months
A6: Sales Representative | B6: 2000 | C6: $/month | D6: 12 | E6: months
A7: General Services Assistant | B7: 0 | C7: $/month | D7: 12 | E7: months
A8: Aquaponics Consultant | B8: 300 | C8: $/hour | D8: 10 | E8: hours
A9: Maintenance | B9: 20 | C9: $/hour | D9: 20 | E9: hours
A10: Legal Consultant | B10: 34.06 | C10: $/hour | D10: 5 | E10: hours
A11: Tax Consultant | B11: 20 | C11: $/hour | D11: 5 | E11: hours
A12: IT maintenance | B12: 25 | C12: $/hour | D12: 52 | E12: hours
A13: Security Services | B13: 0 | C13: $/hour | D13: 8760 | E13: hours
A14: Accountant | B14: 20 | C14: $/hour | D14: 52 | E14: hours
A15: Veterinary | B15: 20 | C15: $/hour | D15: 48 | E15: hours
A16: Laboratory Technitian | B16: 20 | C16: $/hour | D16: 12 | E16: hours
A17: Chemical Technitian | B17: 20 | C17: $/hour | D17: 12 | E17: hours
A19: Operations
A20: Operational people
A21: Crop worker | B21: 1500 | C21: $/month/100m² | D21: 12 | E21: months | F21: =ROUND(HYDROPONIC_AREA/100,0) | G21: workers | I21: COGS (Costs of Goods Sold)
A22: Aquaculture worker | B22: 3000 | C22: $/month/100m² | D22: 12 | E22: months | F22: =ROUND(RAS_AREA/100,0) | G22: workers | I22: =C23+SUM(C25:C35)+E69+D73+SUM(E41:H41)+SUM(E62:H62)
A23: Direct Labor | C23: =B21*D21*F21+B22*D22*F22
A25: Oxygen ($/fish organism) | B25: 0 | C25: =B25*D61
A26: Biologic Surface Area ($/fish tank) | B26: 50 | C26: =B26*FISH_TANK
A27: Carbon Source ($/fish tank) | B27: 0 | C27: =B27*FISH_TANK
A28: Microbiota ($/fish tank) | B28: 0 | C28: =B28*FISH_TANK
A29: Insects ($/fish tank) | B29: 0 | C29: =B29*FISH_TANK
A30: Worms ($/fish tank) | B30: 0 | C30: =B30*FISH_TANK
A31: Pollinator ($/plant) | B31: 0 | C31: =B31*$D$40
A32: Nutrients ($/plant) | B32: 0.15 | C32: =B32*$D$40
A33: Carbon Dioxide ($/plant) | B33: 0 | C33: =B33*$D$40
A34: Controls ($/m2) | B34: 10 | C34: =B34*System_Parameters!O4
A35: Services ($/endeavour) | B35: 0 | C35: =B35
A39: Chosen Greens | B39: Area (m²) | C39: Space ocupied (organism /m²) | D39: # of organism | E39: Younglings ($/organism) | F39: Substrate ($/organism) | G39: Packaging ($/organism) | H39: Logistics ($/organism)
A40: =CHOSEN_GREEN | B40: =HYDROPONIC_AREA | C40: =System_Parameters!D14 | D40: =C40*B40 | E40: =VLOOKUP($A40,$A$42:$H$52,COLUMN(),0) | F40: =VLOOKUP($A40,$A$42:$H$52,COLUMN(),0) | G40: =VLOOKUP($A40,$A$42:$H$52,COLUMN(),0) | H40: =VLOOKUP($A40,$A$42:$H$52,COLUMN(),0)
E41: =E40*D40 | F41: =F40*D40 | G41: =G40*D40 | H41: =H40*D40 | I41: =SUM(E41:H41)
A42: Tomato | E42: 0.5 | F42: =1.4*23 | G42: 5 | H42: 2
A43: Lettuce | B43: Lactuca sativa | E43: 0.04 | F43: 0.014 | G43: 0.1 | H43: 0.2
A44: Chicória | B44: Cichorium intybus | E44: 0.04 | F44: 0.014 | G44: 0.1 | H44: 0.2
A45: Almeirão Pão de Açúcar | B45: Cichorium intybus | E45: 0.04 | F45: 0.014 | G45: 0.1 | H45: 0.2
A46: Almeirão Amargo | B46: Cichorium intybus | E46: 0.04 | F46: 0.014 | G46: 0.1 | H46: 0.2
...
